Workbook
Name Hardware: 'Catálogo Vulnerabilidades'!$C$7:$C$16
Name Organización: 'Catálogo Vulnerabilidades'!$C$71:$C$98
Name Personal: 'Catálogo Vulnerabilidades'!$C$55:$C$62
Name Red: 'Catálogo Vulnerabilidades'!$C$43:$C$52
Name Sitio: 'Catálogo Vulnerabilidades'!$C$65:$C$68
Name Software: 'Catálogo Vulnerabilidades'!$C$19:$C$40
Name Tipo_Activo: 'Valoración de Activos'!$R$8:$R$15
Name Tipo_Soporte: 'Valoración de Activos'!$S$8:$S$15

Sheet Control de cambios
A3: VERSIONAMIENTO
A4: Versión: | B4: 1.4
A5: Fecha de la versión: | B5: 45568
A6: Creado por: | B6: Dirección de Infraestructura Interoperabilidad, Seguridad de la Información y Registro Civil
A7: Aprobado por: | B7: Subsecretaría de Gobierno Electrónico y Registro Civil
A8: Nivel de confidencialidad: | B8: Bajo
A9: Referencia: | B9: ISO/IEC 27005; MAGERIT
A12: Versión | B12: Fecha | C12: Detalle de la modificación
A13: 0.1 | B13: 43497 | C13: Descripción básica del documento
A14: 1.0 | B14: 43721 | C14: Modificación del documento
A15: 1.1 | B15: 43888 | C15: Modificación del documento
A16: 1.3 | B16: 45350 | C16: Actualización del contenido
A17: 1.4 | B17: 45568 | C17: Actualización del contenido

Sheet Tablas de referencia
B2: Tabla de valoración de Impacto en los activos de la información
B4: Valoración del impacto en términos de la perdida de la confidencialidad | C4: Criterio
B5: Alto (3) | C5: La divulgación no autorizada de la información tiene un efecto critico para la institución Ej. Divulgación de información confidencial o sensible.
B6: Medio (2) | C6: La divulgación no autorizada de la información tiene un efecto limitado para la institución Ej. Divulgación de información de uso interno
B7: Bajo (1) | C7: La divulgación de la información no tiene ningún efecto para la institución Ej. Divulgación de información pública.
B9: Valoración del impacto en términos de la perdida de la integridad | C9: Criterio
B10: Alto (3) | C10: La destrucción o modificación no autorizada de la información tiene un efecto severo para la institución
B11: Medio (2) | C11: La destrucción o modificación no autorizada de la información tiene un efecto considerable para la institución
B12: Bajo (1) | C12: La destrucción o modificación de la información tiene un efecto leve para la institución
B14: Valoración del impacto en términos de la perdida de disponibilidad | C14: Criterio
B15: Alto (3) | C15: La interrupción al acceso de la información o los sistemas tienen un efecto severo para la institución
B16: Medio (2) | C16: La interrupción al acceso de la información o los sistemas tienen un efecto considerable para la institución
B17: Bajo (1) | C17: La interrupción al acceso de la información o los sistemas tienen un efecto mínimo para la institución
B20: Estimación de amenazas
B22: Nivel de amenazas | C22: Criterio por probabilidad | D22: Criterio por condición de ocurrencia | E22: Criterio por atractivo | F22: Ejemplo
B23: Alto (3) | C23: La ocurrencia es muy probable (probabilidad > 50%) | D23: Bajo circunstancias normales | E23: El atacante se beneficia en gran medida por el ataque, tiene la capacidad técnica para ejecutarlo y la vulnerabilidad es fácilmente explotable | F23: Código malicioso
B24: Medio (2) | C24: La ocurrencia es probable (probabilidad =50%) | D24: Por errores descuidos | E24: El atacante se beneficia de alguna manera por el ataque, tiene la capacidad técnica para ejecutarlo y la vulnerabilidad es fácilmente explotable | F24: Falla de hardware
B25: Bajo (1) | C25: La ocurrencia es menos probable (probabilidad >0 y <50%) | D25: en rara ocasión | E25: El atacante no se beneficia del ataque | F25: desastres naturales
B27: Estimación de vulnerabilidades
B29: Nivel de vulnerabilidad | C29: Criterio | D29: Ejemplo
B30: Alto (3) | C30: No existe ninguna medida de seguridad implementada para prevenir la ocurrencia de la amenaza | D30: No se utilizan contraseñas para que los usuarios ingresen a los sistemas
B31: Medio (2) | C31: Existen medidas de seguridad implementadas que no reducen la probabilidad de ocurrencia de la amenaza a un nivel aceptable | D31: Existen normas para la utilización de contraseñas pero no se implementa
B32: Bajo (1) | C32: La medida de seguridad es adecuada | D32: Existen normas para la utilización de contraseñas y es aplicada
C36: Relación entre amenaza, vulnerabilidad y pérdida
C45: AMENAZA x VULNERABILIDAD = PÉRDIDA
C46: VIRUS x NO TENER INSTALADO UN SOFTWARE ANTIVIRUS = DESTRUCCIÓN DE DATOS

Sheet Instructivo
B2: INSTRUCTIVO
B4: VALORACIÓN DEL ACTIVO
B6: No | C6: CAMPO | D6: INFORMACIÓN QUE DEBE CONTENER
B7: 1 | C7: Nro. Activo | D7: Asignar el número consecutivo para cada de activo empezando desde A1
B8: 2 | C8: Proceso Macro | D8: Registrar el nombre del proceso macro definido en el alcance del EGSI al cual pertenecen los activos de información
B9: 3 | C9: Subproceso | D9: Registrar el nombre del subproceso que pertenecen los activos de información
B10: 4 | C10: Tipo de Activo | D10: Un activo es un elemento importante con valor para la institución y debe protegerse; los activos incluyen toda información y soporte para el funcionamiento del proceso macro a ser evaluado; se clasifican en: Hardware, software, datos, redes, personal, localización y organización. (de no encontrar lo que necesita modifique el catalogo que se encuentra en la misma página).
B11: 5 | C11: Nombre del Activo | D11: Registrar el nombre del activo de información definido
B12: 6 | C12: Descripción del Activo | D12: Digitar la descripción general del activo de información
B13: 7 | C13: Intensión del uso | D13: Colocar el propósito de uso del activo de información
B14: 8 | C14: Tipos de soporte | D14: Medios en los cuales se contiene la información (de no encontrar lo que necesita modifique el catalogo que se encuentra en la misma página).
B15: 9 | C15: Propietario del Activo | D15: Registrar el nombre del propietario del activo, que es una persona o una entidad a la que la gestión institucional le otorga responsabilidad de administrar el activo de información en su ciclo de vida completo.
B16: 10 | C16: Ubicación | D16: Especificar el lugar donde se encuentran los activos de información
B17: 11 | C17: Valoración del Impacto | D17: Son las consecuencias o efectos que puede ocasionar la materialización del riesgo al proceso y por ende a la institución; valorando la confidencialidad, integridad y disponibilidad de la información
B18: 12 | C18: Confidencialidad | D18: Propiedad que determina que la información no esté disponible; ni sea revelada a individuos, instituciones o procesos no autorizados
... B20: 14 | C20: Disponibilidad | D20: Propiedad de que la información sea accesible, utilizable y/o disponible a los usuarios autorizados cuando estos lo requieran
B22: ANÁLISIS DE RIESGO
B24: 1 | C24: Análisis de Riesgos | D24: Evaluación de las vulnerabilidades que ocasionan amenazas en los activos de información
B25: 2 | C25: Proceso Macro | D25: Registrar el nombre del proceso macro definido en la hoja "Valoración del Activo"
B26: 3 | C26: Subproceso | D26: Registrar el nombre del subproceso definido en la hoja "Valoración del Activo"
B27: 4 | C27: Nro. Activo | D27: Registrar el número de activo definido en la hoja "Valoración del Activo"
B28: 5 | C28: Amenaza | D28: Causa potencial de la ocurrencia de un incidente no deseado, que puede ocasionar daños a un sistema o una organización, para esto tenemos el catalogo respectivo, de no encontrarlo proceder a describir el que se ha identificado.
B29: 6 | C29: Vulnerabilidad | D29: Debilidad de un activo o control, que puede ser explotado por una o más amenazas Ejm. Ausencia de Antivirus, para esto tenemos el catalogo respectivo, de no encontrarlo proceder a describir el que se ha identificado.
B30: 7 | C30: Evaluación de Riesgos | D30: La evaluación del Riesgo permite comparar los resultados de la calificación del riesgo, con los criterios definidos para establecer el grado de exposición de la institución
B31: 8 | C31: Valoración del Impacto | D31: Registrar el valor del Impacto (VA) definido en la hoja "Valoración del Activo"
B32: 9 | C32: Probabilidad | D32: La probabilidad es la medida para estimar la ocurrencia del riesgo
B33: 10 | C33: Nivel de Amenaza | D33: Es la medida para estimar la ocurrencia del riesgo si aprovecha la amenaza definido en la hoja "Tablas de referencia"
B34: 11 | C34: Nivel de Vulnerabilidad | D34: Es la medida para estimar la ocurrencia del riesgo si aprovecha la vulnerabilidad definido en la hoja " Tablas de referencia"
B35: 12 | C35: Controles implementados existentes | D35: Describir si existe un control ya implementado, caso contrario dejar en blanco la celda
... B43: 20 | C43: Riesgo Residual | D43: Es aquel riesgo que subsiste después de haber implementado controles, en esta matriz es considerado "ACEPTABLE" a partir de 3

Sheet Evaluación de Riesgos
B2: Tabla de evaluación del activo | N2: Nivel de Riesgo
B3: Nivel de Amenaza | D3: Bajo (1) | G3: Medio (2) | J3: Alto (3) | N3: 1 | O3: 3 | P3: BAJO
B4: Nivel de Vulnerabilidades | D4: Bajo (1) | E4: Medio (2) | F4: Alto (3) | G4: Bajo (1) | H4: Medio (2) | I4: Alto (3) | J4: Bajo (1) | K4: Medio (2) | L4: Alto (3) | N4: 4 | O4: 8 | P4: MEDIO
B5: Valor del impacto en términos de la pérdida de (CID) en los activos | C5: Bajo (1) | D5: 1 | E5: 2 | F5: 3 | G5: 2 | H5: 4 | I5: 6 | J5: 3 | K5: 6 | L5: 9 | N5: 9 | O5: 27 | P5: ALTO
C6: Medio (2) | D6: 2 | E6: 4 | F6: 6 | G6: 4 | H6: 8 | I6: 12 | J6: 6 | K6: 12 | L6: 18
C7: Alto (3) | D7: 3 | E7: 6 | F7: 9 | G7: 6 | H7: 12 | I7: 18 | J7: 9 | K7: 18 | L7: 27
B9: Evaluación del Riesgo
B10: Proceso de comparación del riesgo estimado contra un criterio de riesgo calculado dado para determinar la importancia del riesgo. El grado del riesgo es expresado numéricamente basado en las medidas del valor de los activos de información, el impacto de la amenaza y el alcance de la vulnerabilidad .
B11: Formula para calcular el grado de riesgo
B12: Riesgo actual = Valor del activo de la información (CID) x Amenaza x Vulnerabilidad

Sheet Opc. Tratamiento Riesgo
C2: Opciones de Tratamiento | F2: Riesgo Residual
C3: MITIGACIÓN, REDUCCIÓN O MODIFICACIÓN DEL RIESGO | D3: Selección de uno o varios controles para reducir el riesgo a un nivel aceptable para la institución ej. Implementar políticas de control de acceso | F3: 1 | G3: 3 | H3: RETENER / ACEPTAR
C4: PREVENCIÓN O EVITACIÓN DEL RIESGO | D4: Eliminar la actividad de alto riesgo o cambiar las condiciones bajo las cuales la actividad es operada (remover el riesgo) | F4: 4 | G4: 27 | H4: MODIFICAR / PREVENIR / COMPARTIR
C5: COMPARTICIÓN DEL RIESGO | D5: Compartir con otra parte que pueda gestionar de manera más efectiva el riesgo particular dependiendo de la valoración de riesgos; implica la decisión de compartir ciertos riesgos con partes externas.
C6: ACEPTACIÓN O RETENCIÓN DEL RIESGO | D6: Tomar la decisión de aceptar las consecuencias de un riesgo en particular, es decir, no se realiza ninguna acción respecto al riesgo

Sheet Valoración de Activos
B2: Listado y valoración de los activos de información
B4: Nro. Activo | C4: Proceso Macro | D4: Subproceso | E4: Tipo de Activo | F4: Nombre de Activo | G4: Descripción del activo | H4: Intención del Uso | I4: Tipo de soporte | J4: Propietario del Activo | K4: Ubicación | L4: Valoración de Impacto (pérdida)
L5: C: Confidencialidad I: Integridad D: Disponibilidad
L6: C | M6: I | N6: D | O6: VA
B7: A1 | C7: Proceso Macro 1 | D7: Subproceso 1 | E7: Software | F7: e-Productos | G7: Sistema para compras en línea | H7: Compras en línea | I7: Virtual en línea | J7: Director de Compras | K7: Amazon Cloud | L7: 3 | M7: 3 | N7: 2 | O7: =(L7+M7+N7)/3 -> 2.6666667 | R7: Tipo_Activo | S7: Tipo_Soporte
B8: A2 | E8: Organización | F8: Activo 2 | L8: 3 | M8: 3 | N8: 2 | O8: =(L8+M8+N8)/3 -> 2.6666667 | R8: Organización | S8: Físico
B9: A3 | E9: Software | F9: Activo 3 | L9: 3 | M9: 3 | N9: 2 | O9: =(L9+M9+N9)/3 -> 2.6666667 | R9: Software | S9: Virtual en línea
B10: A4 | E10: Hardware | F10: Activo 4 | L10: 3 | M10: 3 | N10: 2 | O10: =(L10+M10+N10)/3 -> 2.6666667 | R10: Hardware | S10: Acceso remoto
B11: A5 | E11: Red | F11: Activo 5 | L11: 3 | M11: 3 | N11: 2 | O11: =(L11+M11+N11)/3 -> 2.6666667 | R11: Red | S11: Telefónico
B12: A6 | E12: Personal | F12: Activo 6 | L12: 3 | M12: 3 | N12: 2 | O12: =(L12+M12+N12)/3 -> 2.6666667 | R12: Personal | S12: Físico y Virtual
B13: A7 | E13: Sitio | F13: Activo 7 | L13: 3 | M13: 3 | N13: 2 | O13: =(L13+M13+N13)/3 -> 2.6666667 | R13: Sitio | S13: Físico y Telefónico
B14: A8 | E14: Información | F14: Activo 8 | L14: 3 | M14: 3 | N14: 2 | O14: =(L14+M14+N14)/3 -> 2.6666667 | R14: Información
B15: A9 | E15: Organización | F15: Activo 9 | L15: 3 | M15: 3 | N15: 2 | O15: =(L15+M15+N15)/3 -> 2.6666667
B16: A10 | E16: Software | F16: Activo 10 | L16: 3 | M16: 3 | N16: 2 | O16: =(L16+M16+N16)/3 -> 2.6666667
B17: A11 | E17: Hardware | F17: Activo 11 | L17: 3 | M17: 3 | N17: 2 | O17: =(L17+M17+N17)/3 -> 2.6666667
B18: A12 | E18: Red | F18: Activo 12 | L18: 1 | M18: 1 | N18: 2 | O18: =(L18+M18+N18)/3 -> 1.3333333
B19: A13 | E19: Personal | F19: Activo 13 | L19: 2 | M19: 1 | N19: 2 | O19: =(L19+M19+N19)/3 -> 1.6666667
B20: A14 | E20: Sitio | F20: Activo 14 | L20: 2 | M20: 1 | N20: 2 | O20: =(L20+M20+N20)/3 -> 1.6666667
B21: A15 | E21: Información | F21: Activo 15 | L21: 2 | M21: 1 | N21: 2 | O21: =(L21+M21+N21)/3 -> 1.6666667
B22: A16 | E22: Organización | F22: Activo 16 | L22: 2 | M22: 1 | N22: 1 | O22: =(L22+M22+N22)/3 -> 1.3333333
B23: A17 | E23: Software | F23: Activo 17 | L23: 2 | M23: 1 | N23: 1 | O23: =(L23+M23+N23)/3 -> 1.3333333
B24: A18 | E24: Hardware | F24: Activo 18 | L24: 2 | M24: 1 | N24: 1 | O24: =(L24+M24+N24)/3 -> 1.3333333
B25: A19 | E25: Red | F25: Activo 19 | L25: 2 | M25: 1 | N25: 1 | O25: =(L25+M25+N25)/3 -> 1.3333333
B26: A20 | E26: Personal | F26: Activo 20 | L26: 2 | M26: 1 | N26: 1 | O26: =(L26+M26+N26)/3 -> 1.3333333
... B32: A26 | E32: Red | F32: Activo 26 | L32: 3 | M32: 1 | N32: 1 | O32: =(L32+M32+N32)/3 -> 1.6666667
O33: =IF(MAX(L33:N33)=0," ",MAX(L33:N33))
O34: =IF(MAX(L34:N34)=0," ",MAX(L34:N34))
O35: =IF(MAX(L35:N35)=0," ",MAX(L35:N35))
O36: =IF(MAX(L36:N36)=0," ",MAX(L36:N36))
O37: =IF(MAX(L37:N37)=0," ",MAX(L37:N37))
O38: =IF(MAX(L38:N38)=0," ",MAX(L38:N38))
O39: =IF(MAX(L39:N39)=0," ",MAX(L39:N39))
O40: =IF(MAX(L40:N40)=0," ",MAX(L40:N40))
O41: =IF(MAX(L41:N41)=0," ",MAX(L41:N41))
O42: =IF(MAX(L42:N42)=0," ",MAX(L42:N42))
O43: =IF(MAX(L43:N43)=0," ",MAX(L43:N43))
O44: =IF(MAX(L44:N44)=0," ",MAX(L44:N44))
... O79: =IF(MAX(L79:N79)=0," ",MAX(L79:N79))

Sheet Análisis de Riesgos
B2: Análisis de Riesgos | F2: Evaluación de Riesgos | L2: Tratamiento de Riesgos | S2: Riesgo residual
F3: Impacto | G3: Probabilidad | I3: controles implementados existentes | J3: Cálculo de Evaluación Riesgo | K3: Nivel de Riesgo
B4: Nro. Activo | C4: Nombre Activo | D4: Amenaza | E4: Vulnerabilidad | F4: VA (CID) | G4: Nivel de amenaza | H4: Nivel de vulnerabilidad | L4: Método de tratamiento de Riesgos | M4: Tipo de control | N4: Controles a Implementar | O4: Nivel de amenaza | P4: Nivel de vulnerabilidad | Q4: Cálculo de Evaluación Riesgo con el control implementado | R4: Nivel de Riesgo con el control Implementado
B5: ='Valoración de Activos'!B7 -> A1 | C5: ='Valoración de Activos'!F7 -> e-Productos | D5: Saturación del sistema de información | E5: Servicios innecesarios habilitados | F5: ='Valoración de Activos'!O7 -> 2.6666667 | G5: 3 | H5: 2 | I5: Ninguno | J5: =IF(F5*G5*H5=0," ",F5*G5*H5) -> 16 | K5: =IFERROR(VLOOKUP(J5,'Evaluación de Riesgos'!$N$3:$P$5,3,TRUE),"") -> ALTO | L5: =IFERROR(VLOOKUP(J5,'Opc. Tratamiento Riesgo'!$F$3:$H$4,3,TRUE),"") -> MODIFICAR / PREVENIR / COMPARTIR | M5: =IF(AND(J5>=9,J5<=27),"CONTROL CORRECTIVO",IF(AND(J5>=4,J5<9),"CONTROL PREVENTIVO",IF(AND(J5>=1,J5<4),"MONITOREO Y CONTROL"))) -> CONTROL CORRECTIVO | N5: 4.6 Gestión de la capacidad | O5: 1 | P5: 1 | Q5: =IF($F$5*O5*P5=0," ",$F$5*O5*P5) -> 2.6666667 | R5: =IFERROR(VLOOKUP(Q5,'Evaluación de Riesgos'!$N$3:$P$5,3,TRUE),"") -> BAJO | S5: =IF(Q5=" "," ",IF(Q5<3,"ACEPTABLE","INACEPTABLE")) -> ACEPTABLE
B6: ='Valoración de Activos'!B8 -> A2 | C6: ='Valoración de Activos'!F8 -> Activo 2 | F6: ='Valoración de Activos'!O8 -> 2.6666667 | G6: 1 | H6: 1 | J6: =IF(F6*G6*H6=0," ",F6*G6*H6) -> 2.6666667 | K6: =IFERROR(VLOOKUP(J6,'Evaluación de Riesgos'!$N$3:$P$5,3,TRUE),"") -> BAJO | L6: =IFERROR(VLOOKUP(J6,'Opc. Tratamiento Riesgo'!$F$3:$H$4,3,TRUE),"") -> RETENER / ACEPTAR | M6: =IF(AND(J6>=9,J6<=27),"CONTROL CORRECTIVO",IF(AND(J6>=4,J6<9),"CONTROL PREVENTIVO",IF(AND(J6>=1,J6<4),"MONITOREO Y CONTROL"))) -> MONITOREO Y CONTROL | O6: 1 | P6: 1 | Q6: =IF($F$5*O6*P6=0," ",$F$5*O6*P6) -> 2.6666667 | R6: =IFERROR(VLOOKUP(Q6,'Evaluación de Riesgos'!$N$3:$P$5,3,TRUE),"") -> BAJO | S6: =IF(Q6=" "," ",IF(Q6<3,"ACEPTABLE","INACEPTABLE")) -> ACEPTABLE
B7: ='Valoración de Activos'!B10 -> A4 | C7: ='Valoración de Activos'!F10 -> Activo 4 | F7: ='Valoración de Activos'!O9 -> 2.6666667 | G7: 1 | H7: 1 | J7: =IF(F7*G7*H7=0," ",F7*G7*H7) -> 2.6666667 | K7: =IFERROR(VLOOKUP(J7,'Evaluación de Riesgos'!$N$3:$P$5,3,TRUE),"") -> BAJO | L7: =IFERROR(VLOOKUP(J7,'Opc. Tratamiento Riesgo'!$F$3:$H$4,3,TRUE),"") -> RETENER / ACEPTAR | M7: =IF(AND(J7>=9,J7<=27),"CONTROL CORRECTIVO",IF(AND(J7>=4,J7<9),"CONTROL PREVENTIVO",IF(AND(J7>=1,J7<4),"MONITOREO Y CONTROL"))) -> MONITOREO Y CONTROL | O7: 1 | P7: 1 | Q7: =IF($F$5*O7*P7=0," ",$F$5*O7*P7) -> 2.6666667 | R7: =IFERROR(VLOOKUP(Q7,'Evaluación de Riesgos'!$N$3:$P$5,3,TRUE),"") -> BAJO | S7: =IF(Q7=" "," ",IF(Q7<3,"ACEPTABLE","INACEPTABLE")) -> ACEPTABLE
B8: ='Valoración de Activos'!B11 -> A5 | C8: ='Valoración de Activos'!F11 -> Activo 5 | F8: ='Valoración de Activos'!O10 -> 2.6666667 | G8: 3 | H8: 1 | J8: =IF(F8*G8*H8=0," ",F8*G8*H8) -> 8 | K8: =IFERROR(VLOOKUP(J8,'Evaluación de Riesgos'!$N$3:$P$5,3,TRUE),"") -> MEDIO | L8: =IFERROR(VLOOKUP(J8,'Opc. Tratamiento Riesgo'!$F$3:$H$4,3,TRUE),"") -> MODIFICAR / PREVENIR / COMPARTIR | M8: =IF(AND(J8>=9,J8<=27),"CONTROL CORRECTIVO",IF(AND(J8>=4,J8<9),"CONTROL PREVENTIVO",IF(AND(J8>=1,J8<4),"MONITOREO Y CONTROL"))) -> CONTROL PREVENTIVO | O8: 1 | P8: 1 | Q8: =IF($F$5*O8*P8=0," ",$F$5*O8*P8) -> 2.6666667 | R8: =IFERROR(VLOOKUP(Q8,'Evaluación de Riesgos'!$N$3:$P$5,3,TRUE),"") -> BAJO | S8: =IF(Q8=" "," ",IF(Q8<3,"ACEPTABLE","INACEPTABLE")) -> ACEPTABLE
B9: ='Valoración de Activos'!B12 -> A6 | C9: ='Valoración de Activos'!F12 -> Activo 6 | F9: ='Valoración de Activos'!O11 -> 2.6666667 | G9: 1 | H9: 2 | J9: =IF(F9*G9*H9=0," ",F9*G9*H9) -> 5.3333333 | K9: =IFERROR(VLOOKUP(J9,'Evaluación de Riesgos'!$N$3:$P$5,3,TRUE),"") -> MEDIO | L9: =IFERROR(VLOOKUP(J9,'Opc. Tratamiento Riesgo'!$F$3:$H$4,3,TRUE),"") -> MODIFICAR / PREVENIR / COMPARTIR | M9: =IF(AND(J9>=9,J9<=27),"CONTROL CORRECTIVO",IF(AND(J9>=4,J9<9),"CONTROL PREVENTIVO",IF(AND(J9>=1,J9<4),"MONITOREO Y CONTROL"))) -> CONTROL PREVENTIVO | O9: 1 | P9: 1 | Q9: =IF($F$5*O9*P9=0," ",$F$5*O9*P9) -> 2.6666667 | R9: =IFERROR(VLOOKUP(Q9,'Evaluación de Riesgos'!$N$3:$P$5,3,TRUE),"") -> BAJO | S9: =IF(Q9=" "," ",IF(Q9<3,"ACEPTABLE","INACEPTABLE")) -> ACEPTABLE
B10: ='Valoración de Activos'!B13 -> A7 | C10: ='Valoración de Activos'!F13 -> Activo 7 | F10: ='Valoración de Activos'!O12 -> 2.6666667 | G10: 2 | H10: 2 | J10: =IF(F10*G10*H10=0," ",F10*G10*H10) -> 10.666667 | K10: =IFERROR(VLOOKUP(J10,'Evaluación de Riesgos'!$N$3:$P$5,3,TRUE),"") -> ALTO | L10: =IFERROR(VLOOKUP(J10,'Opc. Tratamiento Riesgo'!$F$3:$H$4,3,TRUE),"") -> MODIFICAR / PREVENIR / COMPARTIR | M10: =IF(AND(J10>=9,J10<=27),"CONTROL CORRECTIVO",IF(AND(J10>=4,J10<9),"CONTROL PREVENTIVO",IF(AND(J10>=1,J10<4),"MONITOREO Y CONTROL"))) -> CONTROL CORRECTIVO | O10: 1 | P10: 1 | Q10: =IF($F$5*O10*P10=0," ",$F$5*O10*P10) -> 2.6666667 | R10: =IFERROR(VLOOKUP(Q10,'Evaluación de Riesgos'!$N$3:$P$5,3,TRUE),"") -> BAJO | S10: =IF(Q10=" "," ",IF(Q10<3,"ACEPTABLE","INACEPTABLE")) -> ACEPTABLE
B11: ='Valoración de Activos'!B14 -> A8 | C11: ='Valoración de Activos'!F14 -> Activo 8 | F11: ='Valoración de Activos'!O13 -> 2.6666667 | G11: 1 | H11: 2 | J11: =IF(F11*G11*H11=0," ",F11*G11*H11) -> 5.3333333 | K11: =IFERROR(VLOOKUP(J11,'Evaluación de Riesgos'!$N$3:$P$5,3,TRUE),"") -> MEDIO | L11: =IFERROR(VLOOKUP(J11,'Opc. Tratamiento Riesgo'!$F$3:$H$4,3,TRUE),"") -> MODIFICAR / PREVENIR / COMPARTIR | M11: =IF(AND(J11>=9,J11<=27),"CONTROL CORRECTIVO",IF(AND(J11>=4,J11<9),"CONTROL PREVENTIVO",IF(AND(J11>=1,J11<4),"MONITOREO Y CONTROL"))) -> CONTROL PREVENTIVO | O11: 1 | P11: 2 | Q11: =IF($F$5*O11*P11=0," ",$F$5*O11*P11) -> 5.3333333 | R11: =IFERROR(VLOOKUP(Q11,'Evaluación de Riesgos'!$N$3:$P$5,3,TRUE),"") -> MEDIO | S11: =IF(Q11=" "," ",IF(Q11<3,"ACEPTABLE","INACEPTABLE")) -> INACEPTABLE
B12: ='Valoración de Activos'!B15 -> A9 | C12: ='Valoración de Activos'!F15 -> Activo 9 | F12: ='Valoración de Activos'!O14 -> 2.6666667 | G12: 1 | H12: 2 | J12: =IF(F12*G12*H12=0," ",F12*G12*H12) -> 5.3333333 | K12: =IFERROR(VLOOKUP(J12,'Evaluación de Riesgos'!$N$3:$P$5,3,TRUE),"") -> MEDIO | L12: =IFERROR(VLOOKUP(J12,'Opc. Tratamiento Riesgo'!$F$3:$H$4,3,TRUE),"") -> MODIFICAR / PREVENIR / COMPARTIR | M12: =IF(AND(J12>=9,J12<=27),"CONTROL CORRECTIVO",IF(AND(J12>=4,J12<9),"CONTROL PREVENTIVO",IF(AND(J12>=1,J12<4),"MONITOREO Y CONTROL"))) -> CONTROL PREVENTIVO | O12: 1 | P12: 1 | Q12: =IF($F$5*O12*P12=0," ",$F$5*O12*P12) -> 2.6666667 | R12: =IFERROR(VLOOKUP(Q12,'Evaluación de Riesgos'!$N$3:$P$5,3,TRUE),"") -> BAJO | S12: =IF(Q12=" "," ",IF(Q12<3,"ACEPTABLE","INACEPTABLE")) -> ACEPTABLE
B13: ='Valoración de Activos'!B17 -> A11 | C13: ='Valoración de Activos'!F16 -> Activo 10 | F13: ='Valoración de Activos'!O15 -> 2.6666667 | G13: 1 | H13: 2 | J13: =IF(F13*G13*H13=0," ",F13*G13*H13) -> 5.3333333 | K13: =IFERROR(VLOOKUP(J13,'Evaluación de Riesgos'!$N$3:$P$5,3,TRUE),"") -> MEDIO | L13: =IFERROR(VLOOKUP(J13,'Opc. Tratamiento Riesgo'!$F$3:$H$4,3,TRUE),"") -> MODIFICAR / PREVENIR / COMPARTIR | M13: =IF(AND(J13>=9,J13<=27),"CONTROL CORRECTIVO",IF(AND(J13>=4,J13<9),"CONTROL PREVENTIVO",IF(AND(J13>=1,J13<4),"MONITOREO Y CONTROL"))) -> CONTROL PREVENTIVO | O13: 1 | P13: 1 | Q13: =IF($F$5*O13*P13=0," ",$F$5*O13*P13) -> 2.6666667 | R13: =IFERROR(VLOOKUP(Q13,'Evaluación de Riesgos'!$N$3:$P$5,3,TRUE),"") -> BAJO | S13: =IF(Q13=" "," ",IF(Q13<3,"ACEPTABLE","INACEPTABLE")) -> ACEPTABLE
B14: ='Valoración de Activos'!B18 -> A12 | C14: ='Valoración de Activos'!F17 -> Activo 11 | F14: ='Valoración de Activos'!O16 -> 2.6666667 | G14: 1 | H14: 2 | J14: =IF(F14*G14*H14=0," ",F14*G14*H14) -> 5.3333333 | K14: =IFERROR(VLOOKUP(J14,'Evaluación de Riesgos'!$N$3:$P$5,3,TRUE),"") -> MEDIO | L14: =IFERROR(VLOOKUP(J14,'Opc. Tratamiento Riesgo'!$F$3:$H$4,3,TRUE),"") -> MODIFICAR / PREVENIR / COMPARTIR | M14: =IF(AND(J14>=9,J14<=27),"CONTROL CORRECTIVO",IF(AND(J14>=4,J14<9),"CONTROL PREVENTIVO",IF(AND(J14>=1,J14<4),"MONITOREO Y CONTROL"))) -> CONTROL PREVENTIVO | O14: 1 | P14: 1 | Q14: =IF($F$5*O14*P14=0," ",$F$5*O14*P14) -> 2.6666667 | R14: =IFERROR(VLOOKUP(Q14,'Evaluación de Riesgos'!$N$3:$P$5,3,TRUE),"") -> BAJO | S14: =IF(Q14=" "," ",IF(Q14<3,"ACEPTABLE","INACEPTABLE")) -> ACEPTABLE
B15: ='Valoración de Activos'!B19 -> A13 | C15: ='Valoración de Activos'!F18 -> Activo 12 | F15: ='Valoración de Activos'!O17 -> 2.6666667 | G15: 1 | H15: 2 | J15: =IF(F15*G15*H15=0," ",F15*G15*H15) -> 5.3333333 | K15: =IFERROR(VLOOKUP(J15,'Evaluación de Riesgos'!$N$3:$P$5,3,TRUE),"") -> MEDIO | L15: =IFERROR(VLOOKUP(J15,'Opc. Tratamiento Riesgo'!$F$3:$H$4,3,TRUE),"") -> MODIFICAR / PREVENIR / COMPARTIR | M15: =IF(AND(J15>=9,J15<=27),"CONTROL CORRECTIVO",IF(AND(J15>=4,J15<9),"CONTROL PREVENTIVO",IF(AND(J15>=1,J15<4),"MONITOREO Y CONTROL"))) -> CONTROL PREVENTIVO | O15: 1 | P15: 1 | Q15: =IF($F$5*O15*P15=0," ",$F$5*O15*P15) -> 2.6666667 | R15: =IFERROR(VLOOKUP(Q15,'Evaluación de Riesgos'!$N$3:$P$5,3,TRUE),"") -> BAJO | S15: =IF(Q15=" "," ",IF(Q15<3,"ACEPTABLE","INACEPTABLE")) -> ACEPTABLE
B16: ='Valoración de Activos'!B20 -> A14 | C16: ='Valoración de Activos'!F19 -> Activo 13 | F16: ='Valoración de Activos'!O18 -> 1.3333333 | G16: 1 | H16: 2 | J16: =IF(F16*G16*H16=0," ",F16*G16*H16) -> 2.6666667 | K16: =IFERROR(VLOOKUP(J16,'Evaluación de Riesgos'!$N$3:$P$5,3,TRUE),"") -> BAJO | L16: =IFERROR(VLOOKUP(J16,'Opc. Tratamiento Riesgo'!$F$3:$H$4,3,TRUE),"") -> RETENER / ACEPTAR | M16: =IF(AND(J16>=9,J16<=27),"CONTROL CORRECTIVO",IF(AND(J16>=4,J16<9),"CONTROL PREVENTIVO",IF(AND(J16>=1,J16<4),"MONITOREO Y CONTROL"))) -> MONITOREO Y CONTROL | O16: 1 | P16: 1 | Q16: =IF($F$5*O16*P16=0," ",$F$5*O16*P16) -> 2.6666667 | R16: =IFERROR(VLOOKUP(Q16,'Evaluación de Riesgos'!$N$3:$P$5,3,TRUE),"") -> BAJO | S16: =IF(Q16=" "," ",IF(Q16<3,"ACEPTABLE","INACEPTABLE")) -> ACEPTABLE
B17: ='Valoración de Activos'!B21 -> A15 | C17: ='Valoración de Activos'!F20 -> Activo 14 | F17: ='Valoración de Activos'!O19 -> 1.6666667 | G17: 3 | H17: 3 | J17: =IF(F17*G17*H17=0," ",F17*G17*H17) -> 15 | K17: =IFERROR(VLOOKUP(J17,'Evaluación de Riesgos'!$N$3:$P$5,3,TRUE),"") -> ALTO | L17: =IFERROR(VLOOKUP(J17,'Opc. Tratamiento Riesgo'!$F$3:$H$4,3,TRUE),"") -> MODIFICAR / PREVENIR / COMPARTIR | M17: =IF(AND(J17>=9,J17<=27),"CONTROL CORRECTIVO",IF(AND(J17>=4,J17<9),"CONTROL PREVENTIVO",IF(AND(J17>=1,J17<4),"MONITOREO Y CONTROL"))) -> CONTROL CORRECTIVO | O17: 1 | P17: 2 | Q17: =IF($F$5*O17*P17=0," ",$F$5*O17*P17) -> 5.3333333 | R17: =IFERROR(VLOOKUP(Q17,'Evaluación de Riesgos'!$N$3:$P$5,3,TRUE),"") -> MEDIO | S17: =IF(Q17=" "," ",IF(Q17<3,"ACEPTABLE","INACEPTABLE")) -> INACEPTABLE
B18: ='Valoración de Activos'!B22 -> A16 | C18: ='Valoración de Activos'!F21 -> Activo 15 | F18: ='Valoración de Activos'!O20 -> 1.6666667 | G18: 2 | H18: 3 | J18: =IF(F18*G18*H18=0," ",F18*G18*H18) -> 10 | K18: =IFERROR(VLOOKUP(J18,'Evaluación de Riesgos'!$N$3:$P$5,3,TRUE),"") -> ALTO | L18: =IFERROR(VLOOKUP(J18,'Opc. Tratamiento Riesgo'!$F$3:$H$4,3,TRUE),"") -> MODIFICAR / PREVENIR / COMPARTIR | M18: =IF(AND(J18>=9,J18<=27),"CONTROL CORRECTIVO",IF(AND(J18>=4,J18<9),"CONTROL PREVENTIVO",IF(AND(J18>=1,J18<4),"MONITOREO Y CONTROL"))) -> CONTROL CORRECTIVO | O18: 1 | P18: 1 | Q18: =IF($F$5*O18*P18=0," ",$F$5*O18*P18) -> 2.6666667 | R18: =IFERROR(VLOOKUP(Q18,'Evaluación de Riesgos'!$N$3:$P$5,3,TRUE),"") -> BAJO | S18: =IF(Q18=" "," ",IF(Q18<3,"ACEPTABLE","INACEPTABLE")) -> ACEPTABLE
B19: ='Valoración de Activos'!B23 -> A17 | C19: ='Valoración de Activos'!F22 -> Activo 16 | F19: ='Valoración de Activos'!O21 -> 1.6666667 | G19: 2 | H19: 2 | J19: =IF(F19*G19*H19=0," ",F19*G19*H19) -> 6.6666667 | K19: =IFERROR(VLOOKUP(J19,'Evaluación de Riesgos'!$N$3:$P$5,3,TRUE),"") -> MEDIO | L19: =IFERROR(VLOOKUP(J19,'Opc. Tratamiento Riesgo'!$F$3:$H$4,3,TRUE),"") -> MODIFICAR / PREVENIR / COMPARTIR | M19: =IF(AND(J19>=9,J19<=27),"CONTROL CORRECTIVO",IF(AND(J19>=4,J19<9),"CONTROL PREVENTIVO",IF(AND(J19>=1,J19<4),"MONITOREO Y CONTROL"))) -> CONTROL PREVENTIVO | O19: 1 | P19: 2 | Q19: =IF($F$5*O19*P19=0," ",$F$5*O19*P19) -> 5.3333333 | R19: =IFERROR(VLOOKUP(Q19,'Evaluación de Riesgos'!$N$3:$P$5,3,TRUE),"") -> MEDIO | S19: =IF(Q19=" "," ",IF(Q19<3,"ACEPTABLE","INACEPTABLE")) -> INACEPTABLE
B20: ='Valoración de Activos'!B24 -> A18 | C20: ='Valoración de Activos'!F23 -> Activo 17 | F20: ='Valoración de Activos'!O22 -> 1.3333333 | G20: 2 | H20: 3 | J20: =IF(F20*G20*H20=0," ",F20*G20*H20) -> 8 | K20: =IFERROR(VLOOKUP(J20,'Evaluación de Riesgos'!$N$3:$P$5,3,TRUE),"") -> MEDIO | L20: =IFERROR(VLOOKUP(J20,'Opc. Tratamiento Riesgo'!$F$3:$H$4,3,TRUE),"") -> MODIFICAR / PREVENIR / COMPARTIR | M20: =IF(AND(J20>=9,J20<=27),"CONTROL CORRECTIVO",IF(AND(J20>=4,J20<9),"CONTROL PREVENTIVO",IF(AND(J20>=1,J20<4),"MONITOREO Y CONTROL"))) -> CONTROL PREVENTIVO | O20: 1 | P20: 1 | Q20: =IF($F$5*O20*P20=0," ",$F$5*O20*P20) -> 2.6666667 | R20: =IFERROR(VLOOKUP(Q20,'Evaluación de Riesgos'!$N$3:$P$5,3,TRUE),"") -> BAJO | S20: =IF(Q20=" "," ",IF(Q20<3,"ACEPTABLE","INACEPTABLE")) -> ACEPTABLE
B21: ='Valoración de Activos'!B25 -> A19 | C21: ='Valoración de Activos'!F24 -> Activo 18 | F21: ='Valoración de Activos'!O23 -> 1.3333333 | G21: 2 | H21: 3 | J21: =IF(F21*G21*H21=0," ",F21*G21*H21) -> 8 | K21: =IFERROR(VLOOKUP(J21,'Evaluación de Riesgos'!$N$3:$P$5,3,TRUE),"") -> MEDIO | L21: =IFERROR(VLOOKUP(J21,'Opc. Tratamiento Riesgo'!$F$3:$H$4,3,TRUE),"") -> MODIFICAR / PREVENIR / COMPARTIR | M21: =IF(AND(J21>=9,J21<=27),"CONTROL CORRECTIVO",IF(AND(J21>=4,J21<9),"CONTROL PREVENTIVO",IF(AND(J21>=1,J21<4),"MONITOREO Y CONTROL"))) -> CONTROL PREVENTIVO | O21: 1 | P21: 1 | Q21: =IF($F$5*O21*P21=0," ",$F$5*O21*P21) -> 2.6666667 | R21: =IFERROR(VLOOKUP(Q21,'Evaluación de Riesgos'!$N$3:$P$5,3,TRUE),"") -> BAJO | S21: =IF(Q21=" "," ",IF(Q21<3,"ACEPTABLE","INACEPTABLE")) -> ACEPTABLE
B22: ='Valoración de Activos'!B26 -> A20 | C22: ='Valoración de Activos'!F25 -> Activo 19 | F22: ='Valoración de Activos'!O24 -> 1.3333333 | G22: 2 | H22: 3 | J22: =IF(F22*G22*H22=0," ",F22*G22*H22) -> 8 | K22: =IFERROR(VLOOKUP(J22,'Evaluación de Riesgos'!$N$3:$P$5,3,TRUE),"") -> MEDIO | L22: =IFERROR(VLOOKUP(J22,'Opc. Tratamiento Riesgo'!$F$3:$H$4,3,TRUE),"") -> MODIFICAR / PREVENIR / COMPARTIR | M22: =IF(AND(J22>=9,J22<=27),"CONTROL CORRECTIVO",IF(AND(J22>=4,J22<9),"CONTROL PREVENTIVO",IF(AND(J22>=1,J22<4),"MONITOREO Y CONTROL"))) -> CONTROL PREVENTIVO | O22: 1 | P22: 1 | Q22: =IF($F$5*O22*P22=0," ",$F$5*O22*P22) -> 2.6666667 | R22: =IFERROR(VLOOKUP(Q22,'Evaluación de Riesgos'!$N$3:$P$5,3,TRUE),"") -> BAJO | S22: =IF(Q22=" "," ",IF(Q22<3,"ACEPTABLE","INACEPTABLE")) -> ACEPTABLE
B23: ='Valoración de Activos'!B27 -> A21 | C23: ='Valoración de Activos'!F26 -> Activo 20 | F23: ='Valoración de Activos'!O25 -> 1.3333333 | G23: 2 | H23: 3 | J23: =IF(F23*G23*H23=0," ",F23*G23*H23) -> 8 | K23: =IFERROR(VLOOKUP(J23,'Evaluación de Riesgos'!$N$3:$P$5,3,TRUE),"") -> MEDIO | L23: =IFERROR(VLOOKUP(J23,'Opc. Tratamiento Riesgo'!$F$3:$H$4,3,TRUE),"") -> MODIFICAR / PREVENIR / COMPARTIR | M23: =IF(AND(J23>=9,J23<=27),"CONTROL CORRECTIVO",IF(AND(J23>=4,J23<9),"CONTROL PREVENTIVO",IF(AND(J23>=1,J23<4),"MONITOREO Y CONTROL"))) -> CONTROL PREVENTIVO | O23: 1 | P23: 2 | Q23: =IF($F$5*O23*P23=0," ",$F$5*O23*P23) -> 5.3333333 | R23: =IFERROR(VLOOKUP(Q23,'Evaluación de Riesgos'!$N$3:$P$5,3,TRUE),"") -> MEDIO | S23: =IF(Q23=" "," ",IF(Q23<3,"ACEPTABLE","INACEPTABLE")) -> INACEPTABLE
B24: ='Valoración de Activos'!B28 -> A22 | C24: ='Valoración de Activos'!F27 -> Activo 21 | F24: ='Valoración de Activos'!O26 -> 1.3333333 | G24: 2 | H24: 1 | J24: =IF(F24*G24*H24=0," ",F24*G24*H24) -> 2.6666667 | K24: =IFERROR(VLOOKUP(J24,'Evaluación de Riesgos'!$N$3:$P$5,3,TRUE),"") -> BAJO | L24: =IFERROR(VLOOKUP(J24,'Opc. Tratamiento Riesgo'!$F$3:$H$4,3,TRUE),"") -> RETENER / ACEPTAR | M24: =IF(AND(J24>=9,J24<=27),"CONTROL CORRECTIVO",IF(AND(J24>=4,J24<9),"CONTROL PREVENTIVO",IF(AND(J24>=1,J24<4),"MONITOREO Y CONTROL"))) -> MONITOREO Y CONTROL | O24: 1 | P24: 1 | Q24: =IF($F$5*O24*P24=0," ",$F$5*O24*P24) -> 2.6666667 | R24: =IFERROR(VLOOKUP(Q24,'Evaluación de Riesgos'!$N$3:$P$5,3,TRUE),"") -> BAJO | S24: =IF(Q24=" "," ",IF(Q24<3,"ACEPTABLE","INACEPTABLE")) -> ACEPTABLE
... B27: ='Valoración de Activos'!B31 -> A25 | C27: ='Valoración de Activos'!F30 -> Activo 24 | F27: ='Valoración de Activos'!O29 -> 1.3333333 | G27: 3 | H27: 3 | J27: =IF(F27*G27*H27=0," ",F27*G27*H27) -> 12 | K27: =IFERROR(VLOOKUP(J27,'Evaluación de Riesgos'!$N$3:$P$5,3,TRUE),"") -> ALTO | L27: =IFERROR(VLOOKUP(J27,'Opc. Tratamiento Riesgo'!$F$3:$H$4,3,TRUE),"") -> MODIFICAR / PREVENIR / COMPARTIR | M27: =IF(AND(J27>=9,J27<=27),"CONTROL CORRECTIVO",IF(AND(J27>=4,J27<9),"CONTROL PREVENTIVO",IF(AND(J27>=1,J27<4),"MONITOREO Y CONTROL"))) -> CONTROL CORRECTIVO | O27: 1 | P27: 2 | Q27: =IF($F$5*O27*P27=0," ",$F$5*O27*P27) -> 5.3333333 | R27: =IFERROR(VLOOKUP(Q27,'Evaluación de Riesgos'!$N$3:$P$5,3,TRUE),"") -> MEDIO | S27: =IF(Q27=" "," ",IF(Q27<3,"ACEPTABLE","INACEPTABLE")) -> INACEPTABLE

Sheet Catálogo Amenazas
B1: SUBSECRETARÍA DE GOBIERNO ELECTRÓNICO Y REGISTRO CIVIL
B3: CATALOGO DE AMENAZAS TÍPICAS Fuente: ISO/IEC 27005:2022
B5: CATEGORIA | C5: AMENAZA | D5: TIPO DE FUENTE DE RIESGO
C6: Amenazas físicas
B7: Amenazas físicas | C7: Fuego | D7: A, D,E | F7: D = deliberado
C8: Agua | D8: A, D, E | F8: A = accidental
C9: Contaminación, radiaciones nocivas | D9: A, D, E | F9: E = ambiental
C10: Accidente grave | D10: A, D, E
C11: Explosión | D11: A, D, E
C12: Polvo, corrosión, congelación | D12: A, D, E
C14: Amenazas naturales
B15: Amenazas naturales | C15: Fenómeno climático | D15: E
C16: Fenómeno sísmico | D16: E
C17: Fenómeno volcánico | D17: E
C18: Fenómeno meteorológico | D18: E
C19: Inundación | D19: E
C20: Pandemia/fenómeno epidémico | D20: E
C22: Fallas en infraestructura
B23: Fallas en infraestructura | C23: Fallo de un sistema de suministro | D23: A, D
C24: Fallo del sistema de refrigeración o ventilación | D24: A, D
C25: Pérdida de suministro eléctrico | D25: A, D, E
C26: Fallo de una red de telecomunicaciones | D26: A, D, E
C27: Radiación electromagnética | D27: A, D, E
C28: Fallo de equipos de telecomunicaciones | D28: A, D
C29: Radiación térmica | D29: A, D, E
C30: Pulsos electromagnéticos | D30: A, D, E
C32: Fallos técnicos
B33: Fallos técnicos | C33: Fallo del dispositivo o sistema | D33: A
C34: Saturación del sistema de información | D34: A, D
C35: Violación de la mantenibilidad del sistema de información | D35: A, D
C37: Acciones humanas
B38: Acciones humanas | C38: Terrorismo, Ataque, sabotaje | D38: D
C39: Ingeniería Social | D39: D
C40: Interceptación de radiación de un dispositivo | D40: D
C41: Espionaje remoto | D41: D
C42: Interceptación de comunicaciones privadas | D42: D
C43: Robo de soportes o documentos | D43: D
C44: Robo de equipos | D44: D
C45: Robo de identidad o credenciales digitales | D45: D
C46: Recuperación de medios reciclados o desechados. | D46: D
...

Sheet Catálogo Vulnerabilidades
B1: SUBSECRETARÍA DE GOBIERNO ELECTRÓNICO Y REGISTRO CIVIL
B3: CATÁLOGO DE VULNERABILIDADES TÍPICAS Fuente: ISO/IEC 27005:2022
B5: CATEGORIA | C5: VULNERABILIDAD
C6: Hardware
B7: Hardware | C7: Mantenimiento insuficiente/instalación defectuosa de los medios de almacenamiento
C8: Susceptibilidad a la humedad, al polvo y a la suciedad
C9: Esquemas de reemplazo periódico insuficientes de equipos
C10: Sensibilidad a la radiación electromagnética
C11: Control de cambios de configuración, insuficiente
C12: Susceptibilidad a las variaciones de tensión
C13: Susceptibilidad a las variaciones de temperatura
C14: Almacenamiento sin protección
C15: Falta de cuidado a disposición
C16: Copia incontrolada
C18: Software
B19: Software | C19: Pruebas de software inexistentes o insuficientes
C20: Defectos conocidos en el software
C21: No “cerrar sesión” al salir de la estación de trabajo
C22: Eliminación o reutilización de medios de almacenamiento sin un borrado adecuado
C23: Configuración insuficiente de los registros para fines de seguimiento de auditoría
C24: Asignación incorrecta de derechos de acceso
C25: Software ampliamente distribuido
C26: Interfaz de usuario complicada
C27: Aplicar programas de aplicación a datos incorrectos en términos de tiempo
C28: Documentación insuficiente o faltante
C29: Configuración de parámetros incorrecta
C30: Fechas incorrectas
C31: Mecanismos de identificación y autenticación insuficientes (por ejemplo, para la autenticación de usuarios)
... C42: Red
B43: Red | C43: Mecanismos insuficientes para la prueba de envío o recepción de un mensaje
C44: Líneas de comunicación no protegidas
C45: Tráfico sensible no protegido
C46: Cableado de unión deficiente
C47: Punto único de falla
C48: Mecanismos ineficaces o falta de identificación y autenticación del remitente y receptor
C49: Arquitectura de red insegura
C50: Transferencia de contraseñas en claro
C51: Gestión inadecuada de la red (resiliencia del enrutamiento)
C52: Conexiones de red pública no protegidas
C54: Personal
...
